2020-01-28 05:57:11,899 WARNING 6213 [enterprise.utils] utils.py:50 - Could not import Registry from third_party_auth.provider
2020-01-28 05:57:11,900 WARNING 6213 [enterprise.utils] utils.py:51 - cannot import name EnterpriseCustomerUser
2020-01-28 06:10:50,102 WARNING 7357 [enterprise.utils] utils.py:50 - Could not import Registry from third_party_auth.provider
2020-01-28 06:10:50,103 WARNING 7357 [enterprise.utils] utils.py:51 - cannot import name EnterpriseCustomerUser
2020-01-28 06:20:21,553 WARNING 8625 [enterprise.utils] utils.py:50 - Could not import Registry from third_party_auth.provider
2020-01-28 06:20:21,553 WARNING 8625 [enterprise.utils] utils.py:51 - cannot import name EnterpriseCustomerUser
2020-01-28 06:20:21,951 WARNING 8635 [enterprise.utils] utils.py:50 - Could not import Registry from third_party_auth.provider
2020-01-28 06:20:21,952 WARNING 8635 [enterprise.utils] utils.py:51 - cannot import name EnterpriseCustomerUser
2020-01-28 06:20:33,849 WARNING 9079 [enterprise.utils] utils.py:50 - Could not import Registry from third_party_auth.provider
2020-01-28 06:20:33,849 WARNING 9079 [enterprise.utils] utils.py:51 - cannot import name EnterpriseCustomerUser
2020-01-28 06:20:36,291 WARNING 9079 [py.warnings] runtime.py:565 - /home/css/edx-edutech/apps/edx/edx-platform/common/lib/xmodule/xmodule/x_module.py:1272: FieldDataDeprecationWarning: Passing field_data as a constructor argument to Runtimes is deprecated
  super(ConfigurableFragmentWrapper, self).__init__(**kwargs)

2020-01-28 06:20:36,491 INFO 9079 [edxval.models] models.py:678 - VAL: Video created with id [a820d0ab-bda0-4e09-89c2-4fad174ef39c] and status [external]
2020-01-28 06:20:36,501 WARNING 9079 [edxval.api] api.py:1132 - [edx-val] "en" transcript "subs_name_of_file.srt.sjson" for video "a820d0ab-bda0-4e09-89c2-4fad174ef39c" is not found.
2020-01-28 06:20:36,718 INFO 9079 [edxval.models] models.py:678 - VAL: Video created with id [a2a3cb38-8b95-4460-bd06-0555004c7e3b] and status [external]
2020-01-28 06:20:36,901 WARNING 9079 [root] mixins.py:522 - XBlock <class 'xblock.internal.DiscussionXBlockWithMixins'> does not contain field url_name
2020-01-28 06:20:37,008 INFO 9079 [edxval.models] models.py:678 - VAL: Video created with id [d776a25f-6ade-4a08-937b-013e4b5fda76] and status [external]
2020-01-28 06:20:37,123 WARNING 9079 [root] mixins.py:522 - XBlock <class 'xblock.internal.DiscussionXBlockWithMixins'> does not contain field url_name
2020-01-28 06:20:37,189 INFO 9079 [edxval.models] models.py:678 - VAL: Video created with id [9bda99ab-0bb6-4cbf-b633-eccec3347661] and status [external]
2020-01-28 06:20:37,291 ERROR 9079 [xmodule.vertical_block] vertical_block.py:170 - Unable to load child when parsing Vertical. Continuing...
Traceback (most recent call last):
  File "/home/css/edx-edutech/apps/edx/edx-platform/common/lib/xmodule/xmodule/vertical_block.py", line 167, in definition_from_xml
    child_block = system.process_xml(etree.tostring(child, encoding='unicode'))
  File "/home/css/edx-edutech/apps/edx/edx-platform/common/lib/xmodule/xmodule/modulestore/xml.py", line 181, in process_xml
    id_manager,
  File "/home/css/edx-edutech/apps/edx/edx-platform/common/lib/xmodule/xmodule/x_module.py", line 1620, in xblock_from_node
    self._convert_reference_fields_to_keys(block)  # difference from XBlock.runtime
  File "/home/css/edx-edutech/apps/edx/edx-platform/common/lib/xmodule/xmodule/x_module.py", line 1665, in _convert_reference_fields_to_keys
    field_value = getattr(xblock, field.name)
  File "/home/css/edx-edutech/apps/edx/venvs/edxapp/lib/python2.7/site-packages/xblock/fields.py", line 519, in __get__
    value = self.from_json(field_data.get(xblock, self.name))
  File "/home/css/edx-edutech/apps/edx/venvs/edxapp/lib/python2.7/site-packages/xblock/fields.py", line 825, in from_json
    raise TypeError('Value stored in a List must be None or a list, found %s' % type(value))
TypeError: Value stored in a List must be None or a list, found <type 'str'>
2020-01-28 06:20:37,293 WARNING 9079 [root] mixins.py:522 - XBlock <class 'xblock.internal.DiscussionXBlockWithMixins'> does not contain field url_name
2020-01-28 06:20:37,357 INFO 9079 [edxval.models] models.py:678 - VAL: Video created with id [c8428dbc-4c30-4e63-a8f9-4399bb39706d] and status [external]
2020-01-28 06:20:37,452 WARNING 9079 [root] mixins.py:522 - XBlock <class 'xblock.internal.DiscussionXBlockWithMixins'> does not contain field url_name
2020-01-28 06:20:37,479 WARNING 9079 [root] mixins.py:522 - XBlock <class 'xblock.internal.DiscussionXBlockWithMixins'> does not contain field url_name
2020-01-28 06:20:37,531 WARNING 9079 [root] mixins.py:522 - XBlock <class 'xblock.internal.DiscussionXBlockWithMixins'> does not contain field url_name
2020-01-28 06:20:37,558 WARNING 9079 [root] mixins.py:522 - XBlock <class 'xblock.internal.DiscussionXBlockWithMixins'> does not contain field url_name
2020-01-28 06:20:37,579 WARNING 9079 [root] mixins.py:522 - XBlock <class 'xblock.internal.DiscussionXBlockWithMixins'> does not contain field url_name
2020-01-28 06:20:37,600 WARNING 9079 [root] mixins.py:522 - XBlock <class 'xblock.internal.DiscussionXBlockWithMixins'> does not contain field url_name
2020-01-28 06:20:37,620 WARNING 9079 [root] mixins.py:522 - XBlock <class 'xblock.internal.DiscussionXBlockWithMixins'> does not contain field url_name
2020-01-28 06:20:37,640 WARNING 9079 [root] mixins.py:522 - XBlock <class 'xblock.internal.DiscussionXBlockWithMixins'> does not contain field url_name
2020-01-28 06:20:37,662 WARNING 9079 [root] mixins.py:522 - XBlock <class 'xblock.internal.DiscussionXBlockWithMixins'> does not contain field url_name
2020-01-28 06:20:37,681 WARNING 9079 [root] mixins.py:522 - XBlock <class 'xblock.internal.DiscussionXBlockWithMixins'> does not contain field url_name
2020-01-28 06:20:37,995 WARNING 9079 [root] mixins.py:522 - XBlock <class 'xblock.internal.DiscussionXBlockWithMixins'> does not contain field url_name
2020-01-28 06:20:38,016 WARNING 9079 [root] mixins.py:522 - XBlock <class 'xblock.internal.DiscussionXBlockWithMixins'> does not contain field url_name
2020-01-28 06:20:38,044 WARNING 9079 [root] mixins.py:522 - XBlock <class 'xblock.internal.DiscussionXBlockWithMixins'> does not contain field url_name
2020-01-28 06:20:38,117 WARNING 9079 [root] mixins.py:522 - XBlock <class 'xblock.internal.DiscussionXBlockWithMixins'> does not contain field url_name
2020-01-28 06:20:38,151 WARNING 9079 [root] mixins.py:522 - XBlock <class 'xblock.internal.DiscussionXBlockWithMixins'> does not contain field url_name
2020-01-28 06:20:38,195 WARNING 9079 [root] mixins.py:522 - XBlock <class 'xblock.internal.DiscussionXBlockWithMixins'> does not contain field url_name
2020-01-28 06:20:38,222 WARNING 9079 [root] mixins.py:522 - XBlock <class 'xblock.internal.DiscussionXBlockWithMixins'> does not contain field url_name
2020-01-28 06:20:38,512 WARNING 9079 [root] mixins.py:522 - XBlock <class 'xblock.internal.DiscussionXBlockWithMixins'> does not contain field url_name
2020-01-28 06:20:38,555 WARNING 9079 [root] mixins.py:522 - XBlock <class 'xblock.internal.DiscussionXBlockWithMixins'> does not contain field url_name
2020-01-28 06:20:38,620 WARNING 9079 [root] mixins.py:522 - XBlock <class 'xblock.internal.DiscussionXBlockWithMixins'> does not contain field url_name
2020-01-28 06:20:38,665 WARNING 9079 [root] mixins.py:522 - XBlock <class 'xblock.internal.DiscussionXBlockWithMixins'> does not contain field url_name
2020-01-28 06:20:38,685 WARNING 9079 [root] mixins.py:522 - XBlock <class 'xblock.internal.DiscussionXBlockWithMixins'> does not contain field url_name
2020-01-28 06:20:38,704 WARNING 9079 [root] mixins.py:522 - XBlock <class 'xblock.internal.DiscussionXBlockWithMixins'> does not contain field url_name
2020-01-28 06:20:38,733 WARNING 9079 [root] mixins.py:522 - XBlock <class 'xblock.internal.DiscussionXBlockWithMixins'> does not contain field url_name
2020-01-28 06:20:38,752 WARNING 9079 [root] mixins.py:522 - XBlock <class 'xblock.internal.DiscussionXBlockWithMixins'> does not contain field url_name
2020-01-28 06:20:38,772 WARNING 9079 [root] mixins.py:522 - XBlock <class 'xblock.internal.DiscussionXBlockWithMixins'> does not contain field url_name
2020-01-28 06:20:38,792 WARNING 9079 [root] mixins.py:522 - XBlock <class 'xblock.internal.DiscussionXBlockWithMixins'> does not contain field url_name
2020-01-28 06:20:38,914 INFO 9079 [xmodule.modulestore.mixed] mixed.py:657 - Creating course run course-v1:edX+DemoX+Demo_Course...
2020-01-28 06:20:38,929 WARNING 9079 [py.warnings] __init__.py:1564 - /home/css/edx-edutech/apps/edx/venvs/edxapp/lib/python2.7/site-packages/pkg_resources/__init__.py:1145: DeprecationWarning: Use of .. or absolute path in a resource path is not allowed and will raise exceptions in a future release.
  self, resource_name

2020-01-28 06:20:39,561 INFO 9079 [openedx.core.djangoapps.content.course_overviews.models] models.py:153 - Creating course overview for course-v1:edX+DemoX+Demo_Course.
2020-01-28 06:20:39,797 INFO 9079 [celery_utils.logged_task] logged_task.py:31 - Task lms.djangoapps.discussion.tasks.update_discussions_map[3c06b349-0218-451d-bc7e-550da541c902] submitted with arguments [{'course_id': u'course-v1:edX+DemoX+Demo_Course'}], None
2020-01-28 06:20:39,818 INFO 9079 [xmodule.modulestore.django] django.py:198 - Sent course_published signal to <function listen_for_course_publish at 0x7f68d9ba6950> with kwargs {'course_key': CourseLocator('edX', 'DemoX', 'Demo_Course', None, None)}. Response was: None
2020-01-28 06:20:39,818 INFO 9079 [xmodule.modulestore.django] django.py:198 - Sent course_published signal to <function _listen_for_course_publish at 0x7f68d99b0150> with kwargs {'course_key': CourseLocator('edX', 'DemoX', 'Demo_Course', None, None)}. Response was: None
2020-01-28 06:20:39,818 INFO 9079 [xmodule.modulestore.django] django.py:198 - Sent course_published signal to <function _listen_for_course_publish at 0x7f68d99bef50> with kwargs {'course_key': CourseLocator('edX', 'DemoX', 'Demo_Course', None, None)}. Response was: None
2020-01-28 06:20:39,819 INFO 9079 [xmodule.modulestore.django] django.py:198 - Sent course_published signal to <function update_block_structure_on_course_publish at 0x7f68d99d10d0> with kwargs {'course_key': CourseLocator('edX', 'DemoX', 'Demo_Course', None, None)}. Response was: None
2020-01-28 06:20:39,819 INFO 9079 [xmodule.modulestore.django] django.py:198 - Sent course_published signal to <function _listen_for_course_publish at 0x7f68d99d16d0> with kwargs {'course_key': CourseLocator('edX', 'DemoX', 'Demo_Course', None, None)}. Response was: None
2020-01-28 06:20:39,819 INFO 9079 [xmodule.modulestore.django] django.py:198 - Sent course_published signal to <function update_discussions_on_course_publish at 0x7f68d9969250> with kwargs {'course_key': CourseLocator('edX', 'DemoX', 'Demo_Course', None, None)}. Response was: None
2020-01-28 06:20:39,819 INFO 9079 [xmodule.modulestore.django] django.py:198 - Sent course_published signal to <function trigger_update_xblocks_cache_task at 0x7f68d9936ed0> with kwargs {'course_key': CourseLocator('edX', 'DemoX', 'Demo_Course', None, None)}. Response was: None
2020-01-28 06:20:39,819 INFO 9079 [xmodule.modulestore.mixed] mixed.py:665 - Course run course-v1:edX+DemoX+Demo_Course created successfully!
2020-01-28 06:20:42,385 ERROR 9079 [root] content.py:461 - Failed to generate thumbnail for asset-v1:edX+DemoX+Demo_Course+type@asset+block@jsmol_Al2O3.png. Exception: cannot identify image file <StringIO.StringIO instance at 0x7f68d90685a0>
Traceback (most recent call last):
  File "/home/css/edx-edutech/apps/edx/edx-platform/common/lib/xmodule/xmodule/contentstore/content.py", line 440, in generate_thumbnail
    with Image.open(source) as image:
  File "/home/css/edx-edutech/apps/edx/venvs/edxapp/lib/python2.7/site-packages/PIL/Image.py", line 2687, in open
    % (filename if filename else fp))
IOError: cannot identify image file <StringIO.StringIO instance at 0x7f68d90685a0>
2020-01-28 06:20:42,405 ERROR 9079 [root] content.py:461 - Failed to generate thumbnail for asset-v1:edX+DemoX+Demo_Course+type@asset+block@jsmol_1hxw.png. Exception: cannot identify image file <StringIO.StringIO instance at 0x7f68d90685a0>
Traceback (most recent call last):
  File "/home/css/edx-edutech/apps/edx/edx-platform/common/lib/xmodule/xmodule/contentstore/content.py", line 440, in generate_thumbnail
    with Image.open(source) as image:
  File "/home/css/edx-edutech/apps/edx/venvs/edxapp/lib/python2.7/site-packages/PIL/Image.py", line 2687, in open
    % (filename if filename else fp))
IOError: cannot identify image file <StringIO.StringIO instance at 0x7f68d90685a0>
2020-01-28 06:20:45,467 INFO 9079 [root] xml_importer.py:352 - No assets.xml file is present with asset metadata.
2020-01-28 06:20:47,832 INFO 9079 [openedx.core.djangoapps.content.course_overviews.models] models.py:150 - Updating course overview for course-v1:edX+DemoX+Demo_Course.
2020-01-28 06:20:47,946 INFO 9079 [openedx.core.djangoapps.content.course_overviews.signals] signals.py:69 - Course start date changed: course=course-v1:edX+DemoX+Demo_Course previous=2030-01-01T00:00:00+00:00 new=2013-02-05T05:00:00+00:00
2020-01-28 06:20:47,971 INFO 9079 [celery_utils.logged_task] logged_task.py:31 - Task openedx.core.djangoapps.schedules.tasks.update_course_schedules[a52fcc47-958b-41c0-9085-8e1ea11c8935] submitted with arguments None, {'course_id': u'course-v1:edX+DemoX+Demo_Course', 'new_upgrade_deadline_str': None, 'new_start_date_str': '2013-02-05T05:00:00+00:00'}
2020-01-28 06:20:48,014 INFO 9079 [celery_utils.logged_task] logged_task.py:31 - Task lms.djangoapps.discussion.tasks.update_discussions_map[00b7fd37-c9c4-4fca-b8f1-10a7dcb0f80e] submitted with arguments [{'course_id': u'course-v1:edX+DemoX+Demo_Course'}], None
2020-01-28 06:20:48,032 INFO 9079 [xmodule.modulestore.django] django.py:198 - Sent course_published signal to <function listen_for_course_publish at 0x7f68d9ba6950> with kwargs {'course_key': CourseLocator('edX', 'DemoX', 'Demo_Course', None, None)}. Response was: None
2020-01-28 06:20:48,032 INFO 9079 [xmodule.modulestore.django] django.py:198 - Sent course_published signal to <function _listen_for_course_publish at 0x7f68d99b0150> with kwargs {'course_key': CourseLocator('edX', 'DemoX', 'Demo_Course', None, None)}. Response was: None
2020-01-28 06:20:48,033 INFO 9079 [xmodule.modulestore.django] django.py:198 - Sent course_published signal to <function _listen_for_course_publish at 0x7f68d99bef50> with kwargs {'course_key': CourseLocator('edX', 'DemoX', 'Demo_Course', None, None)}. Response was: None
2020-01-28 06:20:48,033 INFO 9079 [xmodule.modulestore.django] django.py:198 - Sent course_published signal to <function update_block_structure_on_course_publish at 0x7f68d99d10d0> with kwargs {'course_key': CourseLocator('edX', 'DemoX', 'Demo_Course', None, None)}. Response was: None
2020-01-28 06:20:48,033 INFO 9079 [xmodule.modulestore.django] django.py:198 - Sent course_published signal to <function _listen_for_course_publish at 0x7f68d99d16d0> with kwargs {'course_key': CourseLocator('edX', 'DemoX', 'Demo_Course', None, None)}. Response was: None
2020-01-28 06:20:48,033 INFO 9079 [xmodule.modulestore.django] django.py:198 - Sent course_published signal to <function update_discussions_on_course_publish at 0x7f68d9969250> with kwargs {'course_key': CourseLocator('edX', 'DemoX', 'Demo_Course', None, None)}. Response was: None
2020-01-28 06:20:48,033 INFO 9079 [xmodule.modulestore.django] django.py:198 - Sent course_published signal to <function trigger_update_xblocks_cache_task at 0x7f68d9936ed0> with kwargs {'course_key': CourseLocator('edX', 'DemoX', 'Demo_Course', None, None)}. Response was: None
2020-01-28 06:20:48,048 WARNING 9079 [xmodule.modulestore.xml] xml.py:218 - i4x://edX/DemoX/html/030e35c4756a4ddc8d40b95fbbfff4d4 has more than one definition
2020-01-28 06:20:48,096 INFO 9079 [edxval.models] models.py:678 - VAL: Video created with id [c34e1804-11b0-43c3-9872-45ffe6fd3f5f] and status [external]
2020-01-28 06:20:48,100 WARNING 9079 [edxval.api] api.py:1132 - [edx-val] "en" transcript "subs_name_of_file.srt.sjson" for video "c34e1804-11b0-43c3-9872-45ffe6fd3f5f" is not found.
2020-01-28 06:20:48,203 WARNING 9079 [xmodule.modulestore.xml] xml.py:218 - i4x://edX/DemoX/video/0b9e39477cf34507a7a48f74be381fdd has more than one definition
2020-01-28 06:20:48,229 WARNING 9079 [xmodule.modulestore.xml] xml.py:218 - i4x://edX/DemoX/html/Lab_5B_Mosfet_Amplifier_Experiment has more than one definition
2020-01-28 06:20:48,230 WARNING 9079 [root] mixins.py:522 - XBlock <class 'xblock.internal.DiscussionXBlockWithMixins'> does not contain field url_name
2020-01-28 06:20:48,236 WARNING 9079 [xmodule.modulestore.xml] xml.py:218 - i4x://edX/DemoX/discussion/03f051f9a8814881a3783d2511613aa6 has more than one definition
2020-01-28 06:20:48,386 WARNING 9079 [root] mixins.py:522 - XBlock <class 'xblock.internal.DiscussionXBlockWithMixins'> does not contain field url_name
2020-01-28 06:20:48,408 WARNING 9079 [xmodule.modulestore.xml] xml.py:218 - i4x://edX/DemoX/html/78e3719e864e45f3bee938461f3c3de6 has more than one definition
2020-01-28 06:20:48,417 WARNING 9079 [xmodule.modulestore.xml] xml.py:218 - i4x://edX/DemoX/problem/700x_proteinmake has more than one definition
2020-01-28 06:20:48,418 WARNING 9079 [root] mixins.py:522 - XBlock <class 'xblock.internal.DiscussionXBlockWithMixins'> does not contain field url_name
2020-01-28 06:20:48,425 WARNING 9079 [xmodule.modulestore.xml] xml.py:218 - i4x://edX/DemoX/discussion/ed01bcd164e64038a78964a16eac3edc has more than one definition
2020-01-28 06:20:48,467 WARNING 9079 [xmodule.modulestore.xml] xml.py:218 - i4x://edX/DemoX/html/2b94658d2eee4d85ae13f83bc24cfca9 has more than one definition
2020-01-28 06:20:48,476 WARNING 9079 [xmodule.modulestore.xml] xml.py:218 - i4x://edX/DemoX/problem/700x_editmolB has more than one definition
2020-01-28 06:20:48,477 WARNING 9079 [root] mixins.py:522 - XBlock <class 'xblock.internal.DiscussionXBlockWithMixins'> does not contain field url_name
2020-01-28 06:20:48,485 WARNING 9079 [xmodule.modulestore.xml] xml.py:218 - i4x://edX/DemoX/discussion/0aa7a3bdbe18427795b0c1a1d7c3cb9a has more than one definition
2020-01-28 06:20:48,531 INFO 9079 [edxval.models] models.py:678 - VAL: Video created with id [2c0e8a84-32b9-4c99-a5d2-95fd61bc5d2f] and status [external]
2020-01-28 06:20:48,539 WARNING 9079 [edxval.api] api.py:1132 - [edx-val] "en" transcript "subs_3_yD_cEKoCk.srt.sjson" for video "2c0e8a84-32b9-4c99-a5d2-95fd61bc5d2f" is not found.
2020-01-28 06:20:48,576 WARNING 9079 [xmodule.modulestore.xml] xml.py:218 - i4x://edX/DemoX/html/d45779ad3d024a40a09ad8cc317c0970 has more than one definition
2020-01-28 06:20:48,582 WARNING 9079 [xmodule.modulestore.xml] xml.py:218 - i4x://edX/DemoX/html/55cbc99f262443d886a25cf84594eafb has more than one definition
2020-01-28 06:20:48,583 WARNING 9079 [root] mixins.py:522 - XBlock <class 'xblock.internal.DiscussionXBlockWithMixins'> does not contain field url_name
2020-01-28 06:20:48,589 WARNING 9079 [xmodule.modulestore.xml] xml.py:218 - i4x://edX/DemoX/discussion/ade92343df3d4953a40ab3adc8805390 has more than one definition
2020-01-28 06:20:48,602 WARNING 9079 [xmodule.modulestore.xml] xml.py:218 - i4x://edX/DemoX/problem/Sample_ChemFormula_Problem has more than one definition
2020-01-28 06:20:48,603 WARNING 9079 [root] mixins.py:522 - XBlock <class 'xblock.internal.DiscussionXBlockWithMixins'> does not contain field url_name
2020-01-28 06:20:48,611 WARNING 9079 [xmodule.modulestore.xml] xml.py:218 - i4x://edX/DemoX/discussion/4d672c5893cb4f1dad0de67d2008522e has more than one definition
2020-01-28 06:20:48,623 WARNING 9079 [xmodule.modulestore.xml] xml.py:218 - i4x://edX/DemoX/html/ed5dccf14ae94353961f46fa07217491 has more than one definition
2020-01-28 06:20:48,673 INFO 9079 [edxval.models] models.py:678 - VAL: Video created with id [be3d93fc-ae55-4388-8c72-5bb81097d48d] and status [external]
2020-01-28 06:20:48,768 ERROR 9079 [xmodule.vertical_block] vertical_block.py:170 - Unable to load child when parsing Vertical. Continuing...
Traceback (most recent call last):
  File "/home/css/edx-edutech/apps/edx/edx-platform/common/lib/xmodule/xmodule/vertical_block.py", line 167, in definition_from_xml
    child_block = system.process_xml(etree.tostring(child, encoding='unicode'))
  File "/home/css/edx-edutech/apps/edx/edx-platform/common/lib/xmodule/xmodule/modulestore/xml.py", line 181, in process_xml
    id_manager,
  File "/home/css/edx-edutech/apps/edx/edx-platform/common/lib/xmodule/xmodule/x_module.py", line 1620, in xblock_from_node
    self._convert_reference_fields_to_keys(block)  # difference from XBlock.runtime
  File "/home/css/edx-edutech/apps/edx/edx-platform/common/lib/xmodule/xmodule/x_module.py", line 1665, in _convert_reference_fields_to_keys
    field_value = getattr(xblock, field.name)
  File "/home/css/edx-edutech/apps/edx/venvs/edxapp/lib/python2.7/site-packages/xblock/fields.py", line 519, in __get__
    value = self.from_json(field_data.get(xblock, self.name))
  File "/home/css/edx-edutech/apps/edx/venvs/edxapp/lib/python2.7/site-packages/xblock/fields.py", line 825, in from_json
    raise TypeError('Value stored in a List must be None or a list, found %s' % type(value))
TypeError: Value stored in a List must be None or a list, found <type 'str'>
2020-01-28 06:20:48,769 WARNING 9079 [root] mixins.py:522 - XBlock <class 'xblock.internal.DiscussionXBlockWithMixins'> does not contain field url_name
2020-01-28 06:20:48,782 WARNING 9079 [xmodule.modulestore.xml] xml.py:218 - i4x://edX/DemoX/discussion/9f9e1373cc8243b985c8750cc8acec7d has more than one definition
2020-01-28 06:20:48,788 WARNING 9079 [xmodule.modulestore.xml] xml.py:154 - Non-unique url_name in xml.  This may break state tracking for content.  url_name=New_Unit.  Content=<vertical display_name="New Unit" parent_sequential_url="i4x://edX/DemoX/sequential/07bc32474380492c
2020-01-28 06:20:48,807 WARNING 9079 [xmodule.modulestore.xml] xml.py:218 - i4x://edX/DemoX/openassessment/b24c33ea35954c7889e1d2944d3fe397 has more than one definition
2020-01-28 06:20:48,808 WARNING 9079 [root] mixins.py:522 - XBlock <class 'xblock.internal.DiscussionXBlockWithMixins'> does not contain field url_name
2020-01-28 06:20:48,816 WARNING 9079 [xmodule.modulestore.xml] xml.py:218 - i4x://edX/DemoX/discussion/12ad4f3ff4c14114a6e629b00e000976 has more than one definition
2020-01-28 06:20:48,823 WARNING 9079 [xmodule.modulestore.xml] xml.py:154 - Non-unique url_name in xml.  This may break state tracking for content.  url_name=Video_Demonstrations.  Content=<vertical display_name="Video Demonstrations" parent_sequential_url="i4x://edX/DemoX/sequential/19a3
2020-01-28 06:20:48,875 INFO 9079 [edxval.models] models.py:678 - VAL: Video created with id [fcaf873e-0037-42af-9c6f-de6213b3c6bb] and status [external]
2020-01-28 06:20:49,747 INFO 9079 [openedx.core.djangoapps.content.course_overviews.models] models.py:150 - Updating course overview for course-v1:edX+DemoX+Demo_Course.
2020-01-28 06:20:49,848 INFO 9079 [celery_utils.logged_task] logged_task.py:31 - Task lms.djangoapps.discussion.tasks.update_discussions_map[4500b7ba-701a-4dbc-a096-874675e78348] submitted with arguments [{'course_id': u'course-v1:edX+DemoX+Demo_Course'}], None
2020-01-28 06:20:49,866 INFO 9079 [xmodule.modulestore.django] django.py:198 - Sent course_published signal to <function listen_for_course_publish at 0x7f68d9ba6950> with kwargs {'course_key': CourseLocator('edX', 'DemoX', 'Demo_Course', None, None)}. Response was: None
2020-01-28 06:20:49,866 INFO 9079 [xmodule.modulestore.django] django.py:198 - Sent course_published signal to <function _listen_for_course_publish at 0x7f68d99b0150> with kwargs {'course_key': CourseLocator('edX', 'DemoX', 'Demo_Course', None, None)}. Response was: None
2020-01-28 06:20:49,867 INFO 9079 [xmodule.modulestore.django] django.py:198 - Sent course_published signal to <function _listen_for_course_publish at 0x7f68d99bef50> with kwargs {'course_key': CourseLocator('edX', 'DemoX', 'Demo_Course', None, None)}. Response was: None
2020-01-28 06:20:49,867 INFO 9079 [xmodule.modulestore.django] django.py:198 - Sent course_published signal to <function update_block_structure_on_course_publish at 0x7f68d99d10d0> with kwargs {'course_key': CourseLocator('edX', 'DemoX', 'Demo_Course', None, None)}. Response was: None
2020-01-28 06:20:49,867 INFO 9079 [xmodule.modulestore.django] django.py:198 - Sent course_published signal to <function _listen_for_course_publish at 0x7f68d99d16d0> with kwargs {'course_key': CourseLocator('edX', 'DemoX', 'Demo_Course', None, None)}. Response was: None
2020-01-28 06:20:49,867 INFO 9079 [xmodule.modulestore.django] django.py:198 - Sent course_published signal to <function update_discussions_on_course_publish at 0x7f68d9969250> with kwargs {'course_key': CourseLocator('edX', 'DemoX', 'Demo_Course', None, None)}. Response was: None
2020-01-28 06:20:49,867 INFO 9079 [xmodule.modulestore.django] django.py:198 - Sent course_published signal to <function trigger_update_xblocks_cache_task at 0x7f68d9936ed0> with kwargs {'course_key': CourseLocator('edX', 'DemoX', 'Demo_Course', None, None)}. Response was: None
2020-01-28 06:38:25,786 WARNING 21405 [enterprise.utils] utils.py:50 - Could not import Registry from third_party_auth.provider
2020-01-28 06:38:25,786 WARNING 21405 [enterprise.utils] utils.py:51 - cannot import name EnterpriseCustomerUser
2020-01-28 08:25:49,632 WARNING 15761 [enterprise.utils] utils.py:50 - Could not import Registry from third_party_auth.provider
2020-01-28 08:25:49,632 WARNING 15761 [enterprise.utils] utils.py:51 - cannot import name EnterpriseCustomerUser
2020-01-28 08:25:49,984 WARNING 15745 [enterprise.utils] utils.py:50 - Could not import Registry from third_party_auth.provider
2020-01-28 08:25:49,985 WARNING 15745 [enterprise.utils] utils.py:51 - cannot import name EnterpriseCustomerUser
2020-01-28 11:00:56,261 WARNING 15745 [enterprise.utils] utils.py:50 - Could not import Registry from third_party_auth.provider
2020-01-28 11:00:56,261 WARNING 15745 [enterprise.utils] utils.py:51 - cannot import name EnterpriseCustomerUser
2020-01-28 11:00:56,396 WARNING 15761 [enterprise.utils] utils.py:50 - Could not import Registry from third_party_auth.provider
2020-01-28 11:00:56,396 WARNING 15761 [enterprise.utils] utils.py:51 - cannot import name EnterpriseCustomerUser
2020-01-29 00:01:43,351 WARNING 6435 [enterprise.utils] utils.py:50 - Could not import Registry from third_party_auth.provider
2020-01-29 00:01:43,369 WARNING 6435 [enterprise.utils] utils.py:51 - cannot import name EnterpriseCustomerUser
2020-01-29 00:01:43,415 WARNING 6465 [enterprise.utils] utils.py:50 - Could not import Registry from third_party_auth.provider
2020-01-29 00:01:43,415 WARNING 6465 [enterprise.utils] utils.py:51 - cannot import name EnterpriseCustomerUser
2020-01-29 01:48:55,352 WARNING 25189 [enterprise.utils] utils.py:50 - Could not import Registry from third_party_auth.provider
2020-01-29 01:48:55,352 WARNING 25189 [enterprise.utils] utils.py:51 - cannot import name EnterpriseCustomerUser
2020-01-29 01:55:41,278 WARNING 31789 [enterprise.utils] utils.py:50 - Could not import Registry from third_party_auth.provider
2020-01-29 01:55:41,278 WARNING 31789 [enterprise.utils] utils.py:51 - cannot import name EnterpriseCustomerUser
2020-01-29 01:55:41,280 WARNING 31775 [enterprise.utils] utils.py:50 - Could not import Registry from third_party_auth.provider
2020-01-29 01:55:41,280 WARNING 31775 [enterprise.utils] utils.py:51 - cannot import name EnterpriseCustomerUser
2020-01-29 02:35:33,678 WARNING 400 [enterprise.utils] utils.py:50 - Could not import Registry from third_party_auth.provider
2020-01-29 02:35:33,679 WARNING 400 [enterprise.utils] utils.py:51 - cannot import name EnterpriseCustomerUser
2020-01-29 02:48:08,397 WARNING 12268 [enterprise.utils] utils.py:50 - Could not import Registry from third_party_auth.provider
2020-01-29 02:48:08,398 WARNING 12268 [enterprise.utils] utils.py:51 - cannot import name EnterpriseCustomerUser
2020-01-29 13:15:25,882 WARNING 31775 [enterprise.utils] utils.py:50 - Could not import Registry from third_party_auth.provider
2020-01-29 13:15:25,882 WARNING 31775 [enterprise.utils] utils.py:51 - cannot import name EnterpriseCustomerUser
2020-01-29 13:15:26,214 WARNING 31789 [enterprise.utils] utils.py:50 - Could not import Registry from third_party_auth.provider
2020-01-29 13:15:26,214 WARNING 31789 [enterprise.utils] utils.py:51 - cannot import name EnterpriseCustomerUser
2020-01-30 00:07:44,979 WARNING 7889 [enterprise.utils] utils.py:50 - Could not import Registry from third_party_auth.provider
2020-01-30 00:07:44,992 WARNING 7889 [enterprise.utils] utils.py:51 - cannot import name EnterpriseCustomerUser
2020-01-30 00:07:45,011 WARNING 7870 [enterprise.utils] utils.py:50 - Could not import Registry from third_party_auth.provider
2020-01-30 00:07:45,011 WARNING 7870 [enterprise.utils] utils.py:51 - cannot import name EnterpriseCustomerUser
2020-01-30 00:12:06,752 WARNING 12226 [enterprise.utils] utils.py:50 - Could not import Registry from third_party_auth.provider
2020-01-30 00:12:06,752 WARNING 12226 [enterprise.utils] utils.py:51 - cannot import name EnterpriseCustomerUser
2020-01-30 00:14:32,494 WARNING 14068 [enterprise.utils] utils.py:50 - Could not import Registry from third_party_auth.provider
2020-01-30 00:14:32,494 WARNING 14068 [enterprise.utils] utils.py:51 - cannot import name EnterpriseCustomerUser
2020-01-30 00:14:46,505 WARNING 14273 [enterprise.utils] utils.py:50 - Could not import Registry from third_party_auth.provider
2020-01-30 00:14:46,505 WARNING 14273 [enterprise.utils] utils.py:51 - cannot import name EnterpriseCustomerUser
2020-01-30 00:16:24,175 WARNING 15218 [enterprise.utils] utils.py:50 - Could not import Registry from third_party_auth.provider
2020-01-30 00:16:24,175 WARNING 15218 [enterprise.utils] utils.py:51 - cannot import name EnterpriseCustomerUser
2020-01-30 00:16:30,029 WARNING 15217 [enterprise.utils] utils.py:50 - Could not import Registry from third_party_auth.provider
2020-01-30 00:16:30,030 WARNING 15217 [enterprise.utils] utils.py:51 - cannot import name EnterpriseCustomerUser
2020-01-30 01:53:27,926 WARNING 32384 [enterprise.utils] utils.py:50 - Could not import Registry from third_party_auth.provider
2020-01-30 01:53:27,926 WARNING 32384 [enterprise.utils] utils.py:51 - cannot import name EnterpriseCustomerUser
2020-01-30 01:53:28,403 WARNING 32411 [enterprise.utils] utils.py:50 - Could not import Registry from third_party_auth.provider
2020-01-30 01:53:28,404 WARNING 32411 [enterprise.utils] utils.py:51 - cannot import name EnterpriseCustomerUser
2020-01-30 01:53:32,737 INFO 32384 [openedx.core.djangoapps.user_authn.views.register] register.py:70 - 
Registration/ Form file is Run
2020-01-30 01:53:32,748 INFO 32384 [openedx.core.djangoapps.user_api.api] api.py:26 - 
APIIIIIIIIIIIIII/ Form file is Run
2020-01-30 01:53:32,749 INFO 32384 [openedx.core.djangoapps.user_api.views] views.py:45 - 
User api/VIEW.Py/ Form file is Run
2020-01-30 01:53:33,046 INFO 32411 [openedx.core.djangoapps.user_authn.views.register] register.py:70 - 
Registration/ Form file is Run
2020-01-30 01:53:33,079 INFO 32411 [openedx.core.djangoapps.user_api.api] api.py:26 - 
APIIIIIIIIIIIIII/ Form file is Run
2020-01-30 01:53:33,080 INFO 32411 [openedx.core.djangoapps.user_api.views] views.py:45 - 
User api/VIEW.Py/ Form file is Run
2020-01-30 02:08:22,429 WARNING 14193 [enterprise.utils] utils.py:50 - Could not import Registry from third_party_auth.provider
2020-01-30 02:08:22,429 WARNING 14193 [enterprise.utils] utils.py:51 - cannot import name EnterpriseCustomerUser
2020-01-30 02:08:23,388 WARNING 14197 [enterprise.utils] utils.py:50 - Could not import Registry from third_party_auth.provider
2020-01-30 02:08:23,389 WARNING 14197 [enterprise.utils] utils.py:51 - cannot import name EnterpriseCustomerUser
2020-01-30 02:08:25,754 INFO 14193 [student.forms] forms.py:36 - Student/ Form file is Run
2020-01-30 02:08:26,495 INFO 14197 [student.forms] forms.py:36 - Student/ Form file is Run
2020-01-30 02:08:27,617 INFO 14193 [openedx.core.djangoapps.user_authn.views.register] register.py:70 - 
Registration/ Form file is Run
2020-01-30 02:08:27,631 INFO 14193 [openedx.core.djangoapps.user_api.api] api.py:26 - 
APIIIIIIIIIIIIII/ Form file is Run
2020-01-30 02:08:27,631 INFO 14193 [openedx.core.djangoapps.user_api.views] views.py:45 - 
User api/VIEW.Py/ Form file is Run
2020-01-30 02:08:28,586 INFO 14197 [openedx.core.djangoapps.user_authn.views.register] register.py:70 - 
Registration/ Form file is Run
2020-01-30 02:08:28,602 INFO 14197 [openedx.core.djangoapps.user_api.api] api.py:26 - 
APIIIIIIIIIIIIII/ Form file is Run
2020-01-30 02:08:28,602 INFO 14197 [openedx.core.djangoapps.user_api.views] views.py:45 - 
User api/VIEW.Py/ Form file is Run
